Workbook

Sheet Instructions
A1: Mobile Gallery - Daily Worksheet
A2: How to use this file / इस फाइल का इस्तेमाल कैसे करें
A4: Topic / विषय | B4: In English | C4: हिंदी में सरल भाषा
A5: Master sheet मास्टर शीट | B5: This is your source of data. Yellow cells are editable. Add new clients, items, units and prices here. Everything you add here shows up in the dropdowns on the other sheets automatically. | C5: यहाँ आपका पूरा डेटा है। पीले खाने में बदलाव कर सकते हैं। नए ग्राहक, नई चीज़ें, यूनिट और रेट यहीं डालें। यहाँ जो डालोगे वो बाकी शीट के ड्रॉपडाउन में अपने आप आ जाएगा।
A6: Purchase List खरीदी लिस्ट | B6: Fill the Date. In row 4, pick each client name from the yellow dropdown cells above the quantity columns. For every item: pick the item from the dropdown, then type the quantity each client wants. UNIT and TOTAL fill in automatically. | C6: पहले तारीख भरें। पंक्ति 4 में हर पीले खाने में ग्राहक का नाम ड्रॉपडाउन से चुनें। हर सामान के लिए: चीज़ ड्रॉपडाउन से चुनें, फिर हर ग्राहक के नीचे मात्रा लिखें। यूनिट और कुल जोड़ अपने आप आ जाएगा।
A7: Price List प्राइस लिस्ट | B7: Fill the Date and pick the Customer from the dropdown. Then pick items from the dropdown - the rate auto-fills from Master. If you want to quote a different price to this customer, just type over the rate cell. Editing the Master rate changes every non-overridden rate cell. | C7: तारीख भरें और ग्राहक का नाम ड्रॉपडाउन से चुनें। फिर चीज़ें ड्रॉपडाउन से चुनें - रेट मास्टर से अपने आप आ जाएगा। ग्राहक को अलग रेट बताना है तो रेट के खाने में ऊपर से नया नंबर लिख दो। मास्टर में रेट बदलोगे तो जहाँ आपने खुद नहीं लिखा है वहाँ अपने आप बदल जाएगा।
A8: Add a new client नया ग्राहक जोड़ें | B8: Go to Master sheet, column B. Type the new name below the last client. It appears in every dropdown automatically. | C8: मास्टर शीट में जाओ, B कॉलम। सबसे नीचे नया नाम लिख दो। हर ड्रॉपडाउन में अपने आप आ जाएगा।
A9: Add a new item नयी चीज़ जोड़ें | B9: Go to Master sheet. Fill Category (D), Item (E), Default Unit (F), Price (G) in the next empty row. | C9: मास्टर शीट में जाओ। अगली खाली लाइन में Category (D), Item (E), Default Unit (F), Price (G) भर दो।
A10: Update prices रेट बदलें | B10: In Master sheet, column G. Change the price whenever the market rate changes. Any rate cell in Price List that you have not typed over will update automatically. | C10: मास्टर शीट का G कॉलम खोलो। जब भी मार्केट में रेट बदले, यहाँ बदल दो। प्राइस लिस्ट में जो रेट खुद नहीं लिखा है वो अपने आप बदल जाएगा।
A11: Print प्रिंट करें | B11: Press Ctrl + P. Purchase List prints landscape, Price List prints portrait. Header repeats on every page. | C11: Ctrl + P दबाओ। खरीदी लिस्ट landscape में प्रिंट होगी, प्राइस लिस्ट portrait में। हर पन्ने पर हैडर आएगा।
A12: Save daily copy रोज़ नई फाइल | B12: Before starting a new day: File > Save As, name it like '20-Aug-2026 Purchase.xlsx'. Then clear yellow cells to start fresh. Master data stays. | C12: नए दिन की शुरुआत से पहले: File > Save As, नाम रखो जैसे '20-Aug-2026 Purchase.xlsx'। फिर पीले खाने खाली कर दो, नई शुरुआत के लिए। मास्टर डेटा वैसे ही रहेगा।
A13: Colour guide रंग समझें | B13: Yellow = you can edit. Blue = auto-calculated (do not type, or the formula breaks). Dark = header, do not touch. | C13: पीला = आप बदल सकते हैं। नीला = अपने आप आता है (यहाँ न लिखें, वरना फॉर्मूला टूट जाएगा)। गहरा = हैडर, हाथ न लगाएँ।

Sheet Master
A1: Master Data - Mobile Gallery
A2: Yellow cells are editable. Add new rows at the bottom of each list - dropdowns on other sheets update automatically.
A4: Code | B4: Client / Customer Name | D4: Category | E4: Item | F4: Default Unit | G4: Price (Rs.) | I4: Units
A5: FS | B5: Fountainhead School | D5: VEG | E5: POTATO | F5: KG | I5: KG
A6: GD | B6: G International-1 (Dandi) | D6: VEG | E6: ONION | F6: KG | I6: DOZEN
A7: GDG | B7: G International-2 (DG Corp) | D7: VEG | E7: TOMATO | F7: KG | I7: PCS
A8: GM | B8: Gyan Mudra | D8: VEG | E8: GARLIC (LASUN) | F8: KG | I8: GM
A9: JNVV | B9: JNV (Vankal) | D9: VEG | E9: GINGER (ADRAK) | F9: KG | I9: PACKET
A10: JNVB | B10: JNV (Bhajipura) | D10: VEG | E10: GREEN CHILLY | F10: KG | I10: BUNCH
A11: GKU | B11: Gurukrupa (Udhna) | D11: VEG | E11: FAFADA MIRCH | F11: KG | I11: BUNDLE
D12: VEG | E12: CORIANDER (DHANIYA) | F12: KG | I12: BOX
D13: VEG | E13: KOBICH | F13: KG | I13: CRATE
D14: VEG | E14: GAULI FLOWER | F14: KG | I14: LITRE
D15: VEG | E15: BINAPATTE KA FLOWER | F15: KG | I15: GUNI
D16: VEG | E16: LAUKI | F16: KG
D17: VEG | E17: BHINDI | F17: KG
D18: VEG | E18: BRINJAL | F18: KG
D19: VEG | E19: TINDORA | F19: KG
D20: VEG | E20: PARVAL | F20: KG
D21: VEG | E21: TURIYA | F21: KG
D22: VEG | E22: SIMLA MIRCH | F22: KG
D23: VEG | E23: FANSI | F23: KG
D24: VEG | E24: GUVAR | F24: KG
D25: VEG | E25: SARAGVA SING | F25: KG
D26: VEG | E26: GREEN PEACE | F26: KG
D27: VEG | E27: KATARGAM PAP | F27: KG
... D76: OTHER | E76: PAV BHAJI / DABELI PAV | F76: PCS

Sheet Purchase List
A1: Purchase List - Mobile Gallery | Q1: =IF(Master!$B$5="","",Master!$B$5) -> Fountainhead School | R1: =IF(Master!$E$5="","",Master!$E$5) -> POTATO | S1: =IF(Master!$I$5="","",Master!$I$5) -> KG
A2: Date | D2: Notes | Q2: =IF(Master!$B$6="","",Master!$B$6) -> G International-1 (Dandi) | R2: =IF(Master!$E$6="","",Master!$E$6) -> ONION | S2: =IF(Master!$I$6="","",Master!$I$6) -> DOZEN
Q3: =IF(Master!$B$7="","",Master!$B$7) -> G International-2 (DG Corp) | R3: =IF(Master!$E$7="","",Master!$E$7) -> TOMATO | S3: =IF(Master!$I$7="","",Master!$I$7) -> PCS
A4: SR | B4: ITEM | C4: UNIT | P4: TOTAL | Q4: =IF(Master!$B$8="","",Master!$B$8) -> Gyan Mudra | R4: =IF(Master!$E$8="","",Master!$E$8) -> GARLIC (LASUN) | S4: =IF(Master!$I$8="","",Master!$I$8) -> GM
A5: 1 | C5: =IFERROR(IF(B5="","",INDEX(Master!$F$5:$F$200,MATCH(B5,Master!$E$5:$E$200,0))),"") | P5: =IF(SUM(D5:O5)=0,"",SUM(D5:O5)) | Q5: =IF(Master!$B$9="","",Master!$B$9) -> JNV (Vankal) | R5: =IF(Master!$E$9="","",Master!$E$9) -> GINGER (ADRAK) | S5: =IF(Master!$I$9="","",Master!$I$9) -> PACKET
A6: 2 | C6: =IFERROR(IF(B6="","",INDEX(Master!$F$5:$F$200,MATCH(B6,Master!$E$5:$E$200,0))),"") | P6: =IF(SUM(D6:O6)=0,"",SUM(D6:O6)) | Q6: =IF(Master!$B$10="","",Master!$B$10) -> JNV (Bhajipura) | R6: =IF(Master!$E$10="","",Master!$E$10) -> GREEN CHILLY | S6: =IF(Master!$I$10="","",Master!$I$10) -> BUNCH
A7: 3 | C7: =IFERROR(IF(B7="","",INDEX(Master!$F$5:$F$200,MATCH(B7,Master!$E$5:$E$200,0))),"") | P7: =IF(SUM(D7:O7)=0,"",SUM(D7:O7)) | Q7: =IF(Master!$B$11="","",Master!$B$11) -> Gurukrupa (Udhna) | R7: =IF(Master!$E$11="","",Master!$E$11) -> FAFADA MIRCH | S7: =IF(Master!$I$11="","",Master!$I$11) -> BUNDLE
A8: 4 | C8: =IFERROR(IF(B8="","",INDEX(Master!$F$5:$F$200,MATCH(B8,Master!$E$5:$E$200,0))),"") | P8: =IF(SUM(D8:O8)=0,"",SUM(D8:O8)) | Q8: =IF(Master!$B$12="","",Master!$B$12) | R8: =IF(Master!$E$12="","",Master!$E$12) -> CORIANDER (DHANIYA) | S8: =IF(Master!$I$12="","",Master!$I$12) -> BOX
A9: 5 | C9: =IFERROR(IF(B9="","",INDEX(Master!$F$5:$F$200,MATCH(B9,Master!$E$5:$E$200,0))),"") | P9: =IF(SUM(D9:O9)=0,"",SUM(D9:O9)) | Q9: =IF(Master!$B$13="","",Master!$B$13) | R9: =IF(Master!$E$13="","",Master!$E$13) -> KOBICH | S9: =IF(Master!$I$13="","",Master!$I$13) -> CRATE
A10: 6 | C10: =IFERROR(IF(B10="","",INDEX(Master!$F$5:$F$200,MATCH(B10,Master!$E$5:$E$200,0))),"") | P10: =IF(SUM(D10:O10)=0,"",SUM(D10:O10)) | Q10: =IF(Master!$B$14="","",Master!$B$14) | R10: =IF(Master!$E$14="","",Master!$E$14) -> GAULI FLOWER | S10: =IF(Master!$I$14="","",Master!$I$14) -> LITRE
A11: 7 | C11: =IFERROR(IF(B11="","",INDEX(Master!$F$5:$F$200,MATCH(B11,Master!$E$5:$E$200,0))),"") | P11: =IF(SUM(D11:O11)=0,"",SUM(D11:O11)) | Q11: =IF(Master!$B$15="","",Master!$B$15) | R11: =IF(Master!$E$15="","",Master!$E$15) -> BINAPATTE KA FLOWER | S11: =IF(Master!$I$15="","",Master!$I$15) -> GUNI
A12: 8 | C12: =IFERROR(IF(B12="","",INDEX(Master!$F$5:$F$200,MATCH(B12,Master!$E$5:$E$200,0))),"") | P12: =IF(SUM(D12:O12)=0,"",SUM(D12:O12)) | Q12: =IF(Master!$B$16="","",Master!$B$16) | R12: =IF(Master!$E$16="","",Master!$E$16) -> LAUKI | S12: =IF(Master!$I$16="","",Master!$I$16)
A13: 9 | C13: =IFERROR(IF(B13="","",INDEX(Master!$F$5:$F$200,MATCH(B13,Master!$E$5:$E$200,0))),"") | P13: =IF(SUM(D13:O13)=0,"",SUM(D13:O13)) | Q13: =IF(Master!$B$17="","",Master!$B$17) | R13: =IF(Master!$E$17="","",Master!$E$17) -> BHINDI | S13: =IF(Master!$I$17="","",Master!$I$17)
A14: 10 | C14: =IFERROR(IF(B14="","",INDEX(Master!$F$5:$F$200,MATCH(B14,Master!$E$5:$E$200,0))),"") | P14: =IF(SUM(D14:O14)=0,"",SUM(D14:O14)) | Q14: =IF(Master!$B$18="","",Master!$B$18) | R14: =IF(Master!$E$18="","",Master!$E$18) -> BRINJAL | S14: =IF(Master!$I$18="","",Master!$I$18)
A15: 11 | C15: =IFERROR(IF(B15="","",INDEX(Master!$F$5:$F$200,MATCH(B15,Master!$E$5:$E$200,0))),"") | P15: =IF(SUM(D15:O15)=0,"",SUM(D15:O15)) | Q15: =IF(Master!$B$19="","",Master!$B$19) | R15: =IF(Master!$E$19="","",Master!$E$19) -> TINDORA | S15: =IF(Master!$I$19="","",Master!$I$19)
A16: 12 | C16: =IFERROR(IF(B16="","",INDEX(Master!$F$5:$F$200,MATCH(B16,Master!$E$5:$E$200,0))),"") | P16: =IF(SUM(D16:O16)=0,"",SUM(D16:O16)) | Q16: =IF(Master!$B$20="","",Master!$B$20) | R16: =IF(Master!$E$20="","",Master!$E$20) -> PARVAL | S16: =IF(Master!$I$20="","",Master!$I$20)
A17: 13 | C17: =IFERROR(IF(B17="","",INDEX(Master!$F$5:$F$200,MATCH(B17,Master!$E$5:$E$200,0))),"") | P17: =IF(SUM(D17:O17)=0,"",SUM(D17:O17)) | Q17: =IF(Master!$B$21="","",Master!$B$21) | R17: =IF(Master!$E$21="","",Master!$E$21) -> TURIYA | S17: =IF(Master!$I$21="","",Master!$I$21)
A18: 14 | C18: =IFERROR(IF(B18="","",INDEX(Master!$F$5:$F$200,MATCH(B18,Master!$E$5:$E$200,0))),"") | P18: =IF(SUM(D18:O18)=0,"",SUM(D18:O18)) | Q18: =IF(Master!$B$22="","",Master!$B$22) | R18: =IF(Master!$E$22="","",Master!$E$22) -> SIMLA MIRCH | S18: =IF(Master!$I$22="","",Master!$I$22)
A19: 15 | C19: =IFERROR(IF(B19="","",INDEX(Master!$F$5:$F$200,MATCH(B19,Master!$E$5:$E$200,0))),"") | P19: =IF(SUM(D19:O19)=0,"",SUM(D19:O19)) | Q19: =IF(Master!$B$23="","",Master!$B$23) | R19: =IF(Master!$E$23="","",Master!$E$23) -> FANSI | S19: =IF(Master!$I$23="","",Master!$I$23)
A20: 16 | C20: =IFERROR(IF(B20="","",INDEX(Master!$F$5:$F$200,MATCH(B20,Master!$E$5:$E$200,0))),"") | P20: =IF(SUM(D20:O20)=0,"",SUM(D20:O20)) | Q20: =IF(Master!$B$24="","",Master!$B$24) | R20: =IF(Master!$E$24="","",Master!$E$24) -> GUVAR | S20: =IF(Master!$I$24="","",Master!$I$24)
A21: 17 | C21: =IFERROR(IF(B21="","",INDEX(Master!$F$5:$F$200,MATCH(B21,Master!$E$5:$E$200,0))),"") | P21: =IF(SUM(D21:O21)=0,"",SUM(D21:O21)) | Q21: =IF(Master!$B$25="","",Master!$B$25) | R21: =IF(Master!$E$25="","",Master!$E$25) -> SARAGVA SING | S21: =IF(Master!$I$25="","",Master!$I$25)
A22: 18 | C22: =IFERROR(IF(B22="","",INDEX(Master!$F$5:$F$200,MATCH(B22,Master!$E$5:$E$200,0))),"") | P22: =IF(SUM(D22:O22)=0,"",SUM(D22:O22)) | Q22: =IF(Master!$B$26="","",Master!$B$26) | R22: =IF(Master!$E$26="","",Master!$E$26) -> GREEN PEACE | S22: =IF(Master!$I$26="","",Master!$I$26)
A23: 19 | C23: =IFERROR(IF(B23="","",INDEX(Master!$F$5:$F$200,MATCH(B23,Master!$E$5:$E$200,0))),"") | P23: =IF(SUM(D23:O23)=0,"",SUM(D23:O23)) | Q23: =IF(Master!$B$27="","",Master!$B$27) | R23: =IF(Master!$E$27="","",Master!$E$27) -> KATARGAM PAP | S23: =IF(Master!$I$27="","",Master!$I$27)
A24: 20 | C24: =IFERROR(IF(B24="","",INDEX(Master!$F$5:$F$200,MATCH(B24,Master!$E$5:$E$200,0))),"") | P24: =IF(SUM(D24:O24)=0,"",SUM(D24:O24)) | Q24: =IF(Master!$B$28="","",Master!$B$28) | R24: =IF(Master!$E$28="","",Master!$E$28) -> WHITE PUMPKIN | S24: =IF(Master!$I$28="","",Master!$I$28)
A25: 21 | C25: =IFERROR(IF(B25="","",INDEX(Master!$F$5:$F$200,MATCH(B25,Master!$E$5:$E$200,0))),"") | P25: =IF(SUM(D25:O25)=0,"",SUM(D25:O25)) | Q25: =IF(Master!$B$29="","",Master!$B$29) | R25: =IF(Master!$E$29="","",Master!$E$29) -> LEMON | S25: =IF(Master!$I$29="","",Master!$I$29)
A26: 22 | C26: =IFERROR(IF(B26="","",INDEX(Master!$F$5:$F$200,MATCH(B26,Master!$E$5:$E$200,0))),"") | P26: =IF(SUM(D26:O26)=0,"",SUM(D26:O26)) | Q26: =IF(Master!$B$30="","",Master!$B$30) | R26: =IF(Master!$E$30="","",Master!$E$30) -> CARROT (RED) | S26: =IF(Master!$I$30="","",Master!$I$30)
A27: 23 | C27: =IFERROR(IF(B27="","",INDEX(Master!$F$5:$F$200,MATCH(B27,Master!$E$5:$E$200,0))),"") | P27: =IF(SUM(D27:O27)=0,"",SUM(D27:O27)) | Q27: =IF(Master!$B$31="","",Master!$B$31) | R27: =IF(Master!$E$31="","",Master!$E$31) -> CARROT (ORANGE) | S27: =IF(Master!$I$31="","",Master!$I$31)
A28: 24 | C28: =IFERROR(IF(B28="","",INDEX(Master!$F$5:$F$200,MATCH(B28,Master!$E$5:$E$200,0))),"") | P28: =IF(SUM(D28:O28)=0,"",SUM(D28:O28)) | Q28: =IF(Master!$B$32="","",Master!$B$32) | R28: =IF(Master!$E$32="","",Master!$E$32) -> KAKDI | S28: =IF(Master!$I$32="","",Master!$I$32)
A29: 25 | C29: =IFERROR(IF(B29="","",INDEX(Master!$F$5:$F$200,MATCH(B29,Master!$E$5:$E$200,0))),"") | P29: =IF(SUM(D29:O29)=0,"",SUM(D29:O29)) | Q29: =IF(Master!$B$33="","",Master!$B$33) | R29: =IF(Master!$E$33="","",Master!$E$33) -> MOOLI | S29: =IF(Master!$I$33="","",Master!$I$33)
A30: 26 | C30: =IFERROR(IF(B30="","",INDEX(Master!$F$5:$F$200,MATCH(B30,Master!$E$5:$E$200,0))),"") | P30: =IF(SUM(D30:O30)=0,"",SUM(D30:O30)) | Q30: =IF(Master!$B$34="","",Master!$B$34) | R30: =IF(Master!$E$34="","",Master!$E$34) -> BEETROOT | S30: =IF(Master!$I$34="","",Master!$I$34)
A31: 27 | C31: =IFERROR(IF(B31="","",INDEX(Master!$F$5:$F$200,MATCH(B31,Master!$E$5:$E$200,0))),"") | P31: =IF(SUM(D31:O31)=0,"",SUM(D31:O31)) | Q31: =IF(Master!$B$35="","",Master!$B$35) | R31: =IF(Master!$E$35="","",Master!$E$35) -> CORN (MAKKAI) | S31: =IF(Master!$I$35="","",Master!$I$35)
A32: 28 | C32: =IFERROR(IF(B32="","",INDEX(Master!$F$5:$F$200,MATCH(B32,Master!$E$5:$E$200,0))),"") | P32: =IF(SUM(D32:O32)=0,"",SUM(D32:O32)) | Q32: =IF(Master!$B$36="","",Master!$B$36) | R32: =IF(Master!$E$36="","",Master!$E$36) -> METHI | S32: =IF(Master!$I$36="","",Master!$I$36)
A33: 29 | C33: =IFERROR(IF(B33="","",INDEX(Master!$F$5:$F$200,MATCH(B33,Master!$E$5:$E$200,0))),"") | P33: =IF(SUM(D33:O33)=0,"",SUM(D33:O33)) | Q33: =IF(Master!$B$37="","",Master!$B$37) | R33: =IF(Master!$E$37="","",Master!$E$37) -> PALAK | S33: =IF(Master!$I$37="","",Master!$I$37)
A34: 30 | C34: =IFERROR(IF(B34="","",INDEX(Master!$F$5:$F$200,MATCH(B34,Master!$E$5:$E$200,0))),"") | P34: =IF(SUM(D34:O34)=0,"",SUM(D34:O34)) | Q34: =IF(Master!$B$38="","",Master!$B$38) | R34: =IF(Master!$E$38="","",Master!$E$38) -> PUDINA | S34: =IF(Master!$I$38="","",Master!$I$38)
A35: 31 | C35: =IFERROR(IF(B35="","",INDEX(Master!$F$5:$F$200,MATCH(B35,Master!$E$5:$E$200,0))),"") | P35: =IF(SUM(D35:O35)=0,"",SUM(D35:O35)) | Q35: =IF(Master!$B$39="","",Master!$B$39) | R35: =IF(Master!$E$39="","",Master!$E$39) -> KADI PATTA | S35: =IF(Master!$I$39="","",Master!$I$39)
A36: 32 | C36: =IFERROR(IF(B36="","",INDEX(Master!$F$5:$F$200,MATCH(B36,Master!$E$5:$E$200,0))),"") | P36: =IF(SUM(D36:O36)=0,"",SUM(D36:O36)) | Q36: =IF(Master!$B$40="","",Master!$B$40) | R36: =IF(Master!$E$40="","",Master!$E$40) -> GREEN ONION | S36: =IF(Master!$I$40="","",Master!$I$40)
A37: 33 | C37: =IFERROR(IF(B37="","",INDEX(Master!$F$5:$F$200,MATCH(B37,Master!$E$5:$E$200,0))),"") | P37: =IF(SUM(D37:O37)=0,"",SUM(D37:O37)) | Q37: =IF(Master!$B$41="","",Master!$B$41) | R37: =IF(Master!$E$41="","",Master!$E$41) -> KACCHA BANANA
A38: 34 | C38: =IFERROR(IF(B38="","",INDEX(Master!$F$5:$F$200,MATCH(B38,Master!$E$5:$E$200,0))),"") | P38: =IF(SUM(D38:O38)=0,"",SUM(D38:O38)) | Q38: =IF(Master!$B$42="","",Master!$B$42) | R38: =IF(Master!$E$42="","",Master!$E$42) -> RED SIMLA
A39: 35 | C39: =IFERROR(IF(B39="","",INDEX(Master!$F$5:$F$200,MATCH(B39,Master!$E$5:$E$200,0))),"") | P39: =IF(SUM(D39:O39)=0,"",SUM(D39:O39)) | Q39: =IF(Master!$B$43="","",Master!$B$43) | R39: =IF(Master!$E$43="","",Master!$E$43) -> YELLOW SIMLA
A40: 36 | C40: =IFERROR(IF(B40="","",INDEX(Master!$F$5:$F$200,MATCH(B40,Master!$E$5:$E$200,0))),"") | P40: =IF(SUM(D40:O40)=0,"",SUM(D40:O40)) | Q40: =IF(Master!$B$44="","",Master!$B$44) | R40: =IF(Master!$E$44="","",Master!$E$44) -> BROKALI
...

Sheet Price Quote
A1: Price List - Mobile Gallery | F1: =IF(Master!$B$5="","",Master!$B$5) -> Fountainhead School | G1: =IF(Master!$E$5="","",Master!$E$5) -> POTATO | H1: =IF(Master!$I$5="","",Master!$I$5) -> KG
A2: Date | C2: Customer | F2: =IF(Master!$B$6="","",Master!$B$6) -> G International-1 (Dandi) | G2: =IF(Master!$E$6="","",Master!$E$6) -> ONION | H2: =IF(Master!$I$6="","",Master!$I$6) -> DOZEN
F3: =IF(Master!$B$7="","",Master!$B$7) -> G International-2 (DG Corp) | G3: =IF(Master!$E$7="","",Master!$E$7) -> TOMATO | H3: =IF(Master!$I$7="","",Master!$I$7) -> PCS
A4: SR | B4: ITEM | C4: UNIT | D4: RATE (Rs.) | F4: =IF(Master!$B$8="","",Master!$B$8) -> Gyan Mudra | G4: =IF(Master!$E$8="","",Master!$E$8) -> GARLIC (LASUN) | H4: =IF(Master!$I$8="","",Master!$I$8) -> GM
A5: 1 | C5: =IFERROR(IF(B5="","",INDEX(Master!$F$5:$F$200,MATCH(B5,Master!$E$5:$E$200,0))),"") | D5: =IFERROR(IF(B5="","",INDEX(Master!$G$5:$G$200,MATCH(B5,Master!$E$5:$E$200,0))),"") | F5: =IF(Master!$B$9="","",Master!$B$9) -> JNV (Vankal) | G5: =IF(Master!$E$9="","",Master!$E$9) -> GINGER (ADRAK) | H5: =IF(Master!$I$9="","",Master!$I$9) -> PACKET
A6: 2 | C6: =IFERROR(IF(B6="","",INDEX(Master!$F$5:$F$200,MATCH(B6,Master!$E$5:$E$200,0))),"") | D6: =IFERROR(IF(B6="","",INDEX(Master!$G$5:$G$200,MATCH(B6,Master!$E$5:$E$200,0))),"") | F6: =IF(Master!$B$10="","",Master!$B$10) -> JNV (Bhajipura) | G6: =IF(Master!$E$10="","",Master!$E$10) -> GREEN CHILLY | H6: =IF(Master!$I$10="","",Master!$I$10) -> BUNCH
A7: 3 | C7: =IFERROR(IF(B7="","",INDEX(Master!$F$5:$F$200,MATCH(B7,Master!$E$5:$E$200,0))),"") | D7: =IFERROR(IF(B7="","",INDEX(Master!$G$5:$G$200,MATCH(B7,Master!$E$5:$E$200,0))),"") | F7: =IF(Master!$B$11="","",Master!$B$11) -> Gurukrupa (Udhna) | G7: =IF(Master!$E$11="","",Master!$E$11) -> FAFADA MIRCH | H7: =IF(Master!$I$11="","",Master!$I$11) -> BUNDLE
A8: 4 | C8: =IFERROR(IF(B8="","",INDEX(Master!$F$5:$F$200,MATCH(B8,Master!$E$5:$E$200,0))),"") | D8: =IFERROR(IF(B8="","",INDEX(Master!$G$5:$G$200,MATCH(B8,Master!$E$5:$E$200,0))),"") | F8: =IF(Master!$B$12="","",Master!$B$12) | G8: =IF(Master!$E$12="","",Master!$E$12) -> CORIANDER (DHANIYA) | H8: =IF(Master!$I$12="","",Master!$I$12) -> BOX
A9: 5 | C9: =IFERROR(IF(B9="","",INDEX(Master!$F$5:$F$200,MATCH(B9,Master!$E$5:$E$200,0))),"") | D9: =IFERROR(IF(B9="","",INDEX(Master!$G$5:$G$200,MATCH(B9,Master!$E$5:$E$200,0))),"") | F9: =IF(Master!$B$13="","",Master!$B$13) | G9: =IF(Master!$E$13="","",Master!$E$13) -> KOBICH | H9: =IF(Master!$I$13="","",Master!$I$13) -> CRATE
A10: 6 | C10: =IFERROR(IF(B10="","",INDEX(Master!$F$5:$F$200,MATCH(B10,Master!$E$5:$E$200,0))),"") | D10: =IFERROR(IF(B10="","",INDEX(Master!$G$5:$G$200,MATCH(B10,Master!$E$5:$E$200,0))),"") | F10: =IF(Master!$B$14="","",Master!$B$14) | G10: =IF(Master!$E$14="","",Master!$E$14) -> GAULI FLOWER | H10: =IF(Master!$I$14="","",Master!$I$14) -> LITRE
A11: 7 | C11: =IFERROR(IF(B11="","",INDEX(Master!$F$5:$F$200,MATCH(B11,Master!$E$5:$E$200,0))),"") | D11: =IFERROR(IF(B11="","",INDEX(Master!$G$5:$G$200,MATCH(B11,Master!$E$5:$E$200,0))),"") | F11: =IF(Master!$B$15="","",Master!$B$15) | G11: =IF(Master!$E$15="","",Master!$E$15) -> BINAPATTE KA FLOWER | H11: =IF(Master!$I$15="","",Master!$I$15) -> GUNI
A12: 8 | C12: =IFERROR(IF(B12="","",INDEX(Master!$F$5:$F$200,MATCH(B12,Master!$E$5:$E$200,0))),"") | D12: =IFERROR(IF(B12="","",INDEX(Master!$G$5:$G$200,MATCH(B12,Master!$E$5:$E$200,0))),"") | F12: =IF(Master!$B$16="","",Master!$B$16) | G12: =IF(Master!$E$16="","",Master!$E$16) -> LAUKI | H12: =IF(Master!$I$16="","",Master!$I$16)
A13: 9 | C13: =IFERROR(IF(B13="","",INDEX(Master!$F$5:$F$200,MATCH(B13,Master!$E$5:$E$200,0))),"") | D13: =IFERROR(IF(B13="","",INDEX(Master!$G$5:$G$200,MATCH(B13,Master!$E$5:$E$200,0))),"") | F13: =IF(Master!$B$17="","",Master!$B$17) | G13: =IF(Master!$E$17="","",Master!$E$17) -> BHINDI | H13: =IF(Master!$I$17="","",Master!$I$17)
A14: 10 | C14: =IFERROR(IF(B14="","",INDEX(Master!$F$5:$F$200,MATCH(B14,Master!$E$5:$E$200,0))),"") | D14: =IFERROR(IF(B14="","",INDEX(Master!$G$5:$G$200,MATCH(B14,Master!$E$5:$E$200,0))),"") | F14: =IF(Master!$B$18="","",Master!$B$18) | G14: =IF(Master!$E$18="","",Master!$E$18) -> BRINJAL | H14: =IF(Master!$I$18="","",Master!$I$18)
A15: 11 | C15: =IFERROR(IF(B15="","",INDEX(Master!$F$5:$F$200,MATCH(B15,Master!$E$5:$E$200,0))),"") | D15: =IFERROR(IF(B15="","",INDEX(Master!$G$5:$G$200,MATCH(B15,Master!$E$5:$E$200,0))),"") | F15: =IF(Master!$B$19="","",Master!$B$19) | G15: =IF(Master!$E$19="","",Master!$E$19) -> TINDORA | H15: =IF(Master!$I$19="","",Master!$I$19)
A16: 12 | C16: =IFERROR(IF(B16="","",INDEX(Master!$F$5:$F$200,MATCH(B16,Master!$E$5:$E$200,0))),"") | D16: =IFERROR(IF(B16="","",INDEX(Master!$G$5:$G$200,MATCH(B16,Master!$E$5:$E$200,0))),"") | F16: =IF(Master!$B$20="","",Master!$B$20) | G16: =IF(Master!$E$20="","",Master!$E$20) -> PARVAL | H16: =IF(Master!$I$20="","",Master!$I$20)
A17: 13 | C17: =IFERROR(IF(B17="","",INDEX(Master!$F$5:$F$200,MATCH(B17,Master!$E$5:$E$200,0))),"") | D17: =IFERROR(IF(B17="","",INDEX(Master!$G$5:$G$200,MATCH(B17,Master!$E$5:$E$200,0))),"") | F17: =IF(Master!$B$21="","",Master!$B$21) | G17: =IF(Master!$E$21="","",Master!$E$21) -> TURIYA | H17: =IF(Master!$I$21="","",Master!$I$21)
A18: 14 | C18: =IFERROR(IF(B18="","",INDEX(Master!$F$5:$F$200,MATCH(B18,Master!$E$5:$E$200,0))),"") | D18: =IFERROR(IF(B18="","",INDEX(Master!$G$5:$G$200,MATCH(B18,Master!$E$5:$E$200,0))),"") | F18: =IF(Master!$B$22="","",Master!$B$22) | G18: =IF(Master!$E$22="","",Master!$E$22) -> SIMLA MIRCH | H18: =IF(Master!$I$22="","",Master!$I$22)
A19: 15 | C19: =IFERROR(IF(B19="","",INDEX(Master!$F$5:$F$200,MATCH(B19,Master!$E$5:$E$200,0))),"") | D19: =IFERROR(IF(B19="","",INDEX(Master!$G$5:$G$200,MATCH(B19,Master!$E$5:$E$200,0))),"") | F19: =IF(Master!$B$23="","",Master!$B$23) | G19: =IF(Master!$E$23="","",Master!$E$23) -> FANSI | H19: =IF(Master!$I$23="","",Master!$I$23)
A20: 16 | C20: =IFERROR(IF(B20="","",INDEX(Master!$F$5:$F$200,MATCH(B20,Master!$E$5:$E$200,0))),"") | D20: =IFERROR(IF(B20="","",INDEX(Master!$G$5:$G$200,MATCH(B20,Master!$E$5:$E$200,0))),"") | F20: =IF(Master!$B$24="","",Master!$B$24) | G20: =IF(Master!$E$24="","",Master!$E$24) -> GUVAR | H20: =IF(Master!$I$24="","",Master!$I$24)
A21: 17 | C21: =IFERROR(IF(B21="","",INDEX(Master!$F$5:$F$200,MATCH(B21,Master!$E$5:$E$200,0))),"") | D21: =IFERROR(IF(B21="","",INDEX(Master!$G$5:$G$200,MATCH(B21,Master!$E$5:$E$200,0))),"") | F21: =IF(Master!$B$25="","",Master!$B$25) | G21: =IF(Master!$E$25="","",Master!$E$25) -> SARAGVA SING | H21: =IF(Master!$I$25="","",Master!$I$25)
A22: 18 | C22: =IFERROR(IF(B22="","",INDEX(Master!$F$5:$F$200,MATCH(B22,Master!$E$5:$E$200,0))),"") | D22: =IFERROR(IF(B22="","",INDEX(Master!$G$5:$G$200,MATCH(B22,Master!$E$5:$E$200,0))),"") | F22: =IF(Master!$B$26="","",Master!$B$26) | G22: =IF(Master!$E$26="","",Master!$E$26) -> GREEN PEACE | H22: =IF(Master!$I$26="","",Master!$I$26)
A23: 19 | C23: =IFERROR(IF(B23="","",INDEX(Master!$F$5:$F$200,MATCH(B23,Master!$E$5:$E$200,0))),"") | D23: =IFERROR(IF(B23="","",INDEX(Master!$G$5:$G$200,MATCH(B23,Master!$E$5:$E$200,0))),"") | F23: =IF(Master!$B$27="","",Master!$B$27) | G23: =IF(Master!$E$27="","",Master!$E$27) -> KATARGAM PAP | H23: =IF(Master!$I$27="","",Master!$I$27)
A24: 20 | C24: =IFERROR(IF(B24="","",INDEX(Master!$F$5:$F$200,MATCH(B24,Master!$E$5:$E$200,0))),"") | D24: =IFERROR(IF(B24="","",INDEX(Master!$G$5:$G$200,MATCH(B24,Master!$E$5:$E$200,0))),"") | F24: =IF(Master!$B$28="","",Master!$B$28) | G24: =IF(Master!$E$28="","",Master!$E$28) -> WHITE PUMPKIN | H24: =IF(Master!$I$28="","",Master!$I$28)
A25: 21 | C25: =IFERROR(IF(B25="","",INDEX(Master!$F$5:$F$200,MATCH(B25,Master!$E$5:$E$200,0))),"") | D25: =IFERROR(IF(B25="","",INDEX(Master!$G$5:$G$200,MATCH(B25,Master!$E$5:$E$200,0))),"") | F25: =IF(Master!$B$29="","",Master!$B$29) | G25: =IF(Master!$E$29="","",Master!$E$29) -> LEMON | H25: =IF(Master!$I$29="","",Master!$I$29)
A26: 22 | C26: =IFERROR(IF(B26="","",INDEX(Master!$F$5:$F$200,MATCH(B26,Master!$E$5:$E$200,0))),"") | D26: =IFERROR(IF(B26="","",INDEX(Master!$G$5:$G$200,MATCH(B26,Master!$E$5:$E$200,0))),"") | F26: =IF(Master!$B$30="","",Master!$B$30) | G26: =IF(Master!$E$30="","",Master!$E$30) -> CARROT (RED) | H26: =IF(Master!$I$30="","",Master!$I$30)
A27: 23 | C27: =IFERROR(IF(B27="","",INDEX(Master!$F$5:$F$200,MATCH(B27,Master!$E$5:$E$200,0))),"") | D27: =IFERROR(IF(B27="","",INDEX(Master!$G$5:$G$200,MATCH(B27,Master!$E$5:$E$200,0))),"") | F27: =IF(Master!$B$31="","",Master!$B$31) | G27: =IF(Master!$E$31="","",Master!$E$31) -> CARROT (ORANGE) | H27: =IF(Master!$I$31="","",Master!$I$31)
A28: 24 | C28: =IFERROR(IF(B28="","",INDEX(Master!$F$5:$F$200,MATCH(B28,Master!$E$5:$E$200,0))),"") | D28: =IFERROR(IF(B28="","",INDEX(Master!$G$5:$G$200,MATCH(B28,Master!$E$5:$E$200,0))),"") | F28: =IF(Master!$B$32="","",Master!$B$32) | G28: =IF(Master!$E$32="","",Master!$E$32) -> KAKDI | H28: =IF(Master!$I$32="","",Master!$I$32)
A29: 25 | C29: =IFERROR(IF(B29="","",INDEX(Master!$F$5:$F$200,MATCH(B29,Master!$E$5:$E$200,0))),"") | D29: =IFERROR(IF(B29="","",INDEX(Master!$G$5:$G$200,MATCH(B29,Master!$E$5:$E$200,0))),"") | F29: =IF(Master!$B$33="","",Master!$B$33) | G29: =IF(Master!$E$33="","",Master!$E$33) -> MOOLI | H29: =IF(Master!$I$33="","",Master!$I$33)
A30: 26 | C30: =IFERROR(IF(B30="","",INDEX(Master!$F$5:$F$200,MATCH(B30,Master!$E$5:$E$200,0))),"") | D30: =IFERROR(IF(B30="","",INDEX(Master!$G$5:$G$200,MATCH(B30,Master!$E$5:$E$200,0))),"") | F30: =IF(Master!$B$34="","",Master!$B$34) | G30: =IF(Master!$E$34="","",Master!$E$34) -> BEETROOT | H30: =IF(Master!$I$34="","",Master!$I$34)
A31: 27 | C31: =IFERROR(IF(B31="","",INDEX(Master!$F$5:$F$200,MATCH(B31,Master!$E$5:$E$200,0))),"") | D31: =IFERROR(IF(B31="","",INDEX(Master!$G$5:$G$200,MATCH(B31,Master!$E$5:$E$200,0))),"") | F31: =IF(Master!$B$35="","",Master!$B$35) | G31: =IF(Master!$E$35="","",Master!$E$35) -> CORN (MAKKAI) | H31: =IF(Master!$I$35="","",Master!$I$35)
A32: 28 | C32: =IFERROR(IF(B32="","",INDEX(Master!$F$5:$F$200,MATCH(B32,Master!$E$5:$E$200,0))),"") | D32: =IFERROR(IF(B32="","",INDEX(Master!$G$5:$G$200,MATCH(B32,Master!$E$5:$E$200,0))),"") | F32: =IF(Master!$B$36="","",Master!$B$36) | G32: =IF(Master!$E$36="","",Master!$E$36) -> METHI | H32: =IF(Master!$I$36="","",Master!$I$36)
A33: 29 | C33: =IFERROR(IF(B33="","",INDEX(Master!$F$5:$F$200,MATCH(B33,Master!$E$5:$E$200,0))),"") | D33: =IFERROR(IF(B33="","",INDEX(Master!$G$5:$G$200,MATCH(B33,Master!$E$5:$E$200,0))),"") | F33: =IF(Master!$B$37="","",Master!$B$37) | G33: =IF(Master!$E$37="","",Master!$E$37) -> PALAK | H33: =IF(Master!$I$37="","",Master!$I$37)
A34: 30 | C34: =IFERROR(IF(B34="","",INDEX(Master!$F$5:$F$200,MATCH(B34,Master!$E$5:$E$200,0))),"") | D34: =IFERROR(IF(B34="","",INDEX(Master!$G$5:$G$200,MATCH(B34,Master!$E$5:$E$200,0))),"") | F34: =IF(Master!$B$38="","",Master!$B$38) | G34: =IF(Master!$E$38="","",Master!$E$38) -> PUDINA | H34: =IF(Master!$I$38="","",Master!$I$38)
F35: =IF(Master!$B$39="","",Master!$B$39) | G35: =IF(Master!$E$39="","",Master!$E$39) -> KADI PATTA | H35: =IF(Master!$I$39="","",Master!$I$39)
A36: Rate auto-fills from Master. Type over any rate cell to quote a different price for this customer only. | F36: =IF(Master!$B$40="","",Master!$B$40) | G36: =IF(Master!$E$40="","",Master!$E$40) -> GREEN ONION | H36: =IF(Master!$I$40="","",Master!$I$40)
F37: =IF(Master!$B$41="","",Master!$B$41) | G37: =IF(Master!$E$41="","",Master!$E$41) -> KACCHA BANANA
F38: =IF(Master!$B$42="","",Master!$B$42) | G38: =IF(Master!$E$42="","",Master!$E$42) -> RED SIMLA
F39: =IF(Master!$B$43="","",Master!$B$43) | G39: =IF(Master!$E$43="","",Master!$E$43) -> YELLOW SIMLA
F40: =IF(Master!$B$44="","",Master!$B$44) | G40: =IF(Master!$E$44="","",Master!$E$44) -> BROKALI
...
