Workbook

Sheet Instructions
A1: Mobile Gallery - Daily Worksheet
A2: How to use this file / इस फाइल का इस्तेमाल कैसे करें
A4: Topic / विषय | B4: In English | C4: हिंदी में सरल भाषा
A5: Master sheet मास्टर शीट | B5: Master is where prices live. Update prices here anytime - Price List picks them up automatically. Yellow cells are editable. | C5: मास्टर में रेट रखो। यहाँ रेट बदलो - Price List में अपने आप आ जाएगा। पीले खाने बदल सकते हैं।
A6: Dropdown Source block Dropdown Source ब्लॉक | B6: Purchase List (grey columns R / T / V, right of TOTAL) and Price List (grey columns F / H / J) each hold the item / client / unit list that feeds the dropdowns on that sheet. | C6: Purchase List (ग्रे कॉलम R / T / V, TOTAL के दायीं तरफ) और Price List (ग्रे कॉलम F / H / J) में उस शीट के ड्रॉपडाउन के लिए items / clients / units की लिस्ट है।
A7: Add a NEW item नयी चीज़ जोड़ें | B7: Two steps: (1) Master sheet - add category, item name, default unit, price. (2) In Purchase List grey ITEMS column AND Price List grey ITEMS column - type the same item name in the next empty grey cell. It appears in the dropdown immediately. | C7: दो कदम: (1) मास्टर शीट में category, item, unit, price डालो। (2) Purchase List के ग्रे ITEMS कॉलम और Price List के ग्रे ITEMS कॉलम में - अगले खाली खाने में वही नाम लिख दो। तुरंत ड्रॉपडाउन में आ जाएगा।
A8: Add a NEW client नया ग्राहक जोड़ें | B8: Two steps: (1) Master sheet column B. (2) Purchase List grey CLIENTS column AND Price List grey CUSTOMERS column. | C8: दो कदम: (1) मास्टर शीट के B कॉलम में। (2) Purchase List के ग्रे CLIENTS कॉलम और Price List के ग्रे CUSTOMERS कॉलम में।
A9: Add a NEW unit नयी यूनिट | B9: Two steps: (1) Master sheet column I. (2) Purchase List grey UNITS column AND Price List grey UNITS column. | C9: दो कदम: (1) मास्टर I कॉलम में। (2) Purchase List और Price List के ग्रे UNITS कॉलम में।
A10: Update a price रेट बदलें | B10: One step: Master sheet, column G. Any rate cell in Price List that you have NOT typed over updates automatically. | C10: एक कदम: मास्टर शीट, G कॉलम। Price List में जहाँ आपने खुद नहीं लिखा है वो अपने आप बदल जाएगा।
A11: Purchase List खरीदी लिस्ट | B11: Fill Date. In row 4 pick each client from the yellow header dropdowns above the quantity columns. For each item row: pick ITEM from the dropdown, then type quantity for each client. UNIT and TOTAL fill automatically. | C11: तारीख भरें। पंक्ति 4 में हर पीले खाने में ड्रॉपडाउन से ग्राहक चुनें। हर लाइन: चीज़ ड्रॉपडाउन से चुनें, फिर हर ग्राहक की मात्रा लिखें।
A12: Price List प्राइस लिस्ट | B12: Fill Date, pick Customer from dropdown. Pick items - rate auto-fills from Master. To quote a different price for one customer, type over the rate cell. | C12: तारीख भरें, ग्राहक चुनें। चीज़ें चुनें - रेट मास्टर से आ जाएगा। अलग रेट बताना है तो रेट के खाने में ऊपर से नया नंबर लिख दो।
A13: Print प्रिंट | B13: Ctrl + P. Purchase List prints landscape, Price List prints portrait. The grey Dropdown Source block sits outside the print area, so it will NOT print. | C13: Ctrl + P। खरीदी लिस्ट landscape, प्राइस लिस्ट portrait। ग्रे Dropdown Source ब्लॉक प्रिंट नहीं होगा।
A14: Save daily copy रोज़ नई फाइल | B14: File > Save As before starting a new day. Then clear the yellow cells. Master and Dropdown Source blocks stay untouched. | C14: नया दिन शुरू करने से पहले File > Save As। फिर पीले खाने खाली कर दो।
A15: Colour guide रंग समझें | B15: Yellow = editable. Blue = auto-calculated. Dark = header. Grey = Dropdown Source. | C15: पीला = बदल सकते हैं। नीला = अपने आप। गहरा = हैडर। ग्रे = Dropdown Source।

Sheet Master
A1: Master Data - Mobile Gallery
A2: Yellow cells are editable. Update prices here anytime - Price List picks them up automatically.
A4: Code | B4: Client / Customer Name | D4: Category | E4: Item | F4: Default Unit | G4: Price (Rs.) | I4: Units
A5: FS | B5: Fountainhead School | D5: VEG | E5: POTATO | F5: KG | I5: KG
A6: GD | B6: G International-1 (Dandi) | D6: VEG | E6: ONION | F6: KG | I6: DOZEN
A7: GDG | B7: G International-2 (DG Corp) | D7: VEG | E7: TOMATO | F7: KG | I7: PCS
A8: GM | B8: Gyan Mudra | D8: VEG | E8: GARLIC (LASUN) | F8: KG | I8: GM
A9: JNVV | B9: JNV (Vankal) | D9: VEG | E9: GINGER (ADRAK) | F9: KG | I9: PACKET
A10: JNVB | B10: JNV (Bhajipura) | D10: VEG | E10: GREEN CHILLY | F10: KG | I10: BUNCH
A11: GKU | B11: Gurukrupa (Udhna) | D11: VEG | E11: FAFADA MIRCH | F11: KG | I11: BUNDLE
D12: VEG | E12: CORIANDER (DHANIYA) | F12: KG | I12: BOX
D13: VEG | E13: KOBICH | F13: KG | I13: CRATE
D14: VEG | E14: GAULI FLOWER | F14: KG | I14: LITRE
D15: VEG | E15: BINAPATTE KA FLOWER | F15: KG | I15: GUNI
D16: VEG | E16: LAUKI | F16: KG
D17: VEG | E17: BHINDI | F17: KG
D18: VEG | E18: BRINJAL | F18: KG
D19: VEG | E19: TINDORA | F19: KG
D20: VEG | E20: PARVAL | F20: KG
D21: VEG | E21: TURIYA | F21: KG
D22: VEG | E22: SIMLA MIRCH | F22: KG
D23: VEG | E23: FANSI | F23: KG
D24: VEG | E24: GUVAR | F24: KG
D25: VEG | E25: SARAGVA SING | F25: KG
D26: VEG | E26: GREEN PEACE | F26: KG
D27: VEG | E27: KATARGAM PAP | F27: KG
... D76: OTHER | E76: PAV BHAJI / DABELI PAV | F76: PCS

Sheet Purchase List
A1: Purchase List - Mobile Gallery | R1: Dropdown Source - edit here to add new items / clients / units
A2: Date | D2: Notes
R3: ITEMS | T3: CLIENTS | V3: UNITS
A4: SR | B4: ITEM | C4: UNIT | P4: TOTAL | R4: POTATO | T4: Fountainhead School | V4: KG
A5: 1 | C5: =IF(B5="","",IF(ISNA(MATCH(B5,Master!$E$5:$E$200,0)),"",INDEX(Master!$F$5:$F$200,MATCH(B5,Master!$E$5:$E$200,0)))) | P5: =IF(SUM(D5:O5)=0,"",SUM(D5:O5)) | R5: ONION | T5: G International-1 (Dandi) | V5: DOZEN
A6: 2 | C6: =IF(B6="","",IF(ISNA(MATCH(B6,Master!$E$5:$E$200,0)),"",INDEX(Master!$F$5:$F$200,MATCH(B6,Master!$E$5:$E$200,0)))) | P6: =IF(SUM(D6:O6)=0,"",SUM(D6:O6)) | R6: TOMATO | T6: G International-2 (DG Corp) | V6: PCS
A7: 3 | C7: =IF(B7="","",IF(ISNA(MATCH(B7,Master!$E$5:$E$200,0)),"",INDEX(Master!$F$5:$F$200,MATCH(B7,Master!$E$5:$E$200,0)))) | P7: =IF(SUM(D7:O7)=0,"",SUM(D7:O7)) | R7: GARLIC (LASUN) | T7: Gyan Mudra | V7: GM
A8: 4 | C8: =IF(B8="","",IF(ISNA(MATCH(B8,Master!$E$5:$E$200,0)),"",INDEX(Master!$F$5:$F$200,MATCH(B8,Master!$E$5:$E$200,0)))) | P8: =IF(SUM(D8:O8)=0,"",SUM(D8:O8)) | R8: GINGER (ADRAK) | T8: JNV (Vankal) | V8: PACKET
A9: 5 | C9: =IF(B9="","",IF(ISNA(MATCH(B9,Master!$E$5:$E$200,0)),"",INDEX(Master!$F$5:$F$200,MATCH(B9,Master!$E$5:$E$200,0)))) | P9: =IF(SUM(D9:O9)=0,"",SUM(D9:O9)) | R9: GREEN CHILLY | T9: JNV (Bhajipura) | V9: BUNCH
A10: 6 | C10: =IF(B10="","",IF(ISNA(MATCH(B10,Master!$E$5:$E$200,0)),"",INDEX(Master!$F$5:$F$200,MATCH(B10,Master!$E$5:$E$200,0)))) | P10: =IF(SUM(D10:O10)=0,"",SUM(D10:O10)) | R10: FAFADA MIRCH | T10: Gurukrupa (Udhna) | V10: BUNDLE
A11: 7 | C11: =IF(B11="","",IF(ISNA(MATCH(B11,Master!$E$5:$E$200,0)),"",INDEX(Master!$F$5:$F$200,MATCH(B11,Master!$E$5:$E$200,0)))) | P11: =IF(SUM(D11:O11)=0,"",SUM(D11:O11)) | R11: CORIANDER (DHANIYA) | V11: BOX
A12: 8 | C12: =IF(B12="","",IF(ISNA(MATCH(B12,Master!$E$5:$E$200,0)),"",INDEX(Master!$F$5:$F$200,MATCH(B12,Master!$E$5:$E$200,0)))) | P12: =IF(SUM(D12:O12)=0,"",SUM(D12:O12)) | R12: KOBICH | V12: CRATE
A13: 9 | C13: =IF(B13="","",IF(ISNA(MATCH(B13,Master!$E$5:$E$200,0)),"",INDEX(Master!$F$5:$F$200,MATCH(B13,Master!$E$5:$E$200,0)))) | P13: =IF(SUM(D13:O13)=0,"",SUM(D13:O13)) | R13: GAULI FLOWER | V13: LITRE
A14: 10 | C14: =IF(B14="","",IF(ISNA(MATCH(B14,Master!$E$5:$E$200,0)),"",INDEX(Master!$F$5:$F$200,MATCH(B14,Master!$E$5:$E$200,0)))) | P14: =IF(SUM(D14:O14)=0,"",SUM(D14:O14)) | R14: BINAPATTE KA FLOWER | V14: GUNI
A15: 11 | C15: =IF(B15="","",IF(ISNA(MATCH(B15,Master!$E$5:$E$200,0)),"",INDEX(Master!$F$5:$F$200,MATCH(B15,Master!$E$5:$E$200,0)))) | P15: =IF(SUM(D15:O15)=0,"",SUM(D15:O15)) | R15: LAUKI
A16: 12 | C16: =IF(B16="","",IF(ISNA(MATCH(B16,Master!$E$5:$E$200,0)),"",INDEX(Master!$F$5:$F$200,MATCH(B16,Master!$E$5:$E$200,0)))) | P16: =IF(SUM(D16:O16)=0,"",SUM(D16:O16)) | R16: BHINDI
A17: 13 | C17: =IF(B17="","",IF(ISNA(MATCH(B17,Master!$E$5:$E$200,0)),"",INDEX(Master!$F$5:$F$200,MATCH(B17,Master!$E$5:$E$200,0)))) | P17: =IF(SUM(D17:O17)=0,"",SUM(D17:O17)) | R17: BRINJAL
A18: 14 | C18: =IF(B18="","",IF(ISNA(MATCH(B18,Master!$E$5:$E$200,0)),"",INDEX(Master!$F$5:$F$200,MATCH(B18,Master!$E$5:$E$200,0)))) | P18: =IF(SUM(D18:O18)=0,"",SUM(D18:O18)) | R18: TINDORA
A19: 15 | C19: =IF(B19="","",IF(ISNA(MATCH(B19,Master!$E$5:$E$200,0)),"",INDEX(Master!$F$5:$F$200,MATCH(B19,Master!$E$5:$E$200,0)))) | P19: =IF(SUM(D19:O19)=0,"",SUM(D19:O19)) | R19: PARVAL
A20: 16 | C20: =IF(B20="","",IF(ISNA(MATCH(B20,Master!$E$5:$E$200,0)),"",INDEX(Master!$F$5:$F$200,MATCH(B20,Master!$E$5:$E$200,0)))) | P20: =IF(SUM(D20:O20)=0,"",SUM(D20:O20)) | R20: TURIYA
A21: 17 | C21: =IF(B21="","",IF(ISNA(MATCH(B21,Master!$E$5:$E$200,0)),"",INDEX(Master!$F$5:$F$200,MATCH(B21,Master!$E$5:$E$200,0)))) | P21: =IF(SUM(D21:O21)=0,"",SUM(D21:O21)) | R21: SIMLA MIRCH
A22: 18 | C22: =IF(B22="","",IF(ISNA(MATCH(B22,Master!$E$5:$E$200,0)),"",INDEX(Master!$F$5:$F$200,MATCH(B22,Master!$E$5:$E$200,0)))) | P22: =IF(SUM(D22:O22)=0,"",SUM(D22:O22)) | R22: FANSI
A23: 19 | C23: =IF(B23="","",IF(ISNA(MATCH(B23,Master!$E$5:$E$200,0)),"",INDEX(Master!$F$5:$F$200,MATCH(B23,Master!$E$5:$E$200,0)))) | P23: =IF(SUM(D23:O23)=0,"",SUM(D23:O23)) | R23: GUVAR
A24: 20 | C24: =IF(B24="","",IF(ISNA(MATCH(B24,Master!$E$5:$E$200,0)),"",INDEX(Master!$F$5:$F$200,MATCH(B24,Master!$E$5:$E$200,0)))) | P24: =IF(SUM(D24:O24)=0,"",SUM(D24:O24)) | R24: SARAGVA SING
A25: 21 | C25: =IF(B25="","",IF(ISNA(MATCH(B25,Master!$E$5:$E$200,0)),"",INDEX(Master!$F$5:$F$200,MATCH(B25,Master!$E$5:$E$200,0)))) | P25: =IF(SUM(D25:O25)=0,"",SUM(D25:O25)) | R25: GREEN PEACE
A26: 22 | C26: =IF(B26="","",IF(ISNA(MATCH(B26,Master!$E$5:$E$200,0)),"",INDEX(Master!$F$5:$F$200,MATCH(B26,Master!$E$5:$E$200,0)))) | P26: =IF(SUM(D26:O26)=0,"",SUM(D26:O26)) | R26: KATARGAM PAP
... A64: 60 | C64: =IF(B64="","",IF(ISNA(MATCH(B64,Master!$E$5:$E$200,0)),"",INDEX(Master!$F$5:$F$200,MATCH(B64,Master!$E$5:$E$200,0)))) | P64: =IF(SUM(D64:O64)=0,"",SUM(D64:O64)) | R64: MOSAMBI
R65: MUSK MELON
R66: MANGO / STRAWBERRY
R67: PINEAPPLE
R68: NARIYAL PANI
R69: PANIPURI
R70: COLD DRINK
R71: BUTTER
R72: CHEESE
R73: PANEER
R74: BRADE
R75: PAV BHAJI / DABELI PAV

Sheet Price Quote
A1: Price List - Mobile Gallery | F1: Dropdown Source - edit here to add new items / customers / units
A2: Date | C2: Customer
F3: ITEMS | H3: CUSTOMERS | J3: UNITS
A4: SR | B4: ITEM | C4: UNIT | D4: RATE (Rs.) | F4: POTATO | H4: Fountainhead School | J4: KG
A5: 1 | C5: =IF(B5="","",IF(ISNA(MATCH(B5,Master!$E$5:$E$200,0)),"",INDEX(Master!$F$5:$F$200,MATCH(B5,Master!$E$5:$E$200,0)))) | D5: =IF(B5="","",IF(ISNA(MATCH(B5,Master!$E$5:$E$200,0)),"",INDEX(Master!$G$5:$G$200,MATCH(B5,Master!$E$5:$E$200,0)))) | F5: ONION | H5: G International-1 (Dandi) | J5: DOZEN
A6: 2 | C6: =IF(B6="","",IF(ISNA(MATCH(B6,Master!$E$5:$E$200,0)),"",INDEX(Master!$F$5:$F$200,MATCH(B6,Master!$E$5:$E$200,0)))) | D6: =IF(B6="","",IF(ISNA(MATCH(B6,Master!$E$5:$E$200,0)),"",INDEX(Master!$G$5:$G$200,MATCH(B6,Master!$E$5:$E$200,0)))) | F6: TOMATO | H6: G International-2 (DG Corp) | J6: PCS
A7: 3 | C7: =IF(B7="","",IF(ISNA(MATCH(B7,Master!$E$5:$E$200,0)),"",INDEX(Master!$F$5:$F$200,MATCH(B7,Master!$E$5:$E$200,0)))) | D7: =IF(B7="","",IF(ISNA(MATCH(B7,Master!$E$5:$E$200,0)),"",INDEX(Master!$G$5:$G$200,MATCH(B7,Master!$E$5:$E$200,0)))) | F7: GARLIC (LASUN) | H7: Gyan Mudra | J7: GM
A8: 4 | C8: =IF(B8="","",IF(ISNA(MATCH(B8,Master!$E$5:$E$200,0)),"",INDEX(Master!$F$5:$F$200,MATCH(B8,Master!$E$5:$E$200,0)))) | D8: =IF(B8="","",IF(ISNA(MATCH(B8,Master!$E$5:$E$200,0)),"",INDEX(Master!$G$5:$G$200,MATCH(B8,Master!$E$5:$E$200,0)))) | F8: GINGER (ADRAK) | H8: JNV (Vankal) | J8: PACKET
A9: 5 | C9: =IF(B9="","",IF(ISNA(MATCH(B9,Master!$E$5:$E$200,0)),"",INDEX(Master!$F$5:$F$200,MATCH(B9,Master!$E$5:$E$200,0)))) | D9: =IF(B9="","",IF(ISNA(MATCH(B9,Master!$E$5:$E$200,0)),"",INDEX(Master!$G$5:$G$200,MATCH(B9,Master!$E$5:$E$200,0)))) | F9: GREEN CHILLY | H9: JNV (Bhajipura) | J9: BUNCH
A10: 6 | C10: =IF(B10="","",IF(ISNA(MATCH(B10,Master!$E$5:$E$200,0)),"",INDEX(Master!$F$5:$F$200,MATCH(B10,Master!$E$5:$E$200,0)))) | D10: =IF(B10="","",IF(ISNA(MATCH(B10,Master!$E$5:$E$200,0)),"",INDEX(Master!$G$5:$G$200,MATCH(B10,Master!$E$5:$E$200,0)))) | F10: FAFADA MIRCH | H10: Gurukrupa (Udhna) | J10: BUNDLE
A11: 7 | C11: =IF(B11="","",IF(ISNA(MATCH(B11,Master!$E$5:$E$200,0)),"",INDEX(Master!$F$5:$F$200,MATCH(B11,Master!$E$5:$E$200,0)))) | D11: =IF(B11="","",IF(ISNA(MATCH(B11,Master!$E$5:$E$200,0)),"",INDEX(Master!$G$5:$G$200,MATCH(B11,Master!$E$5:$E$200,0)))) | F11: CORIANDER (DHANIYA) | J11: BOX
A12: 8 | C12: =IF(B12="","",IF(ISNA(MATCH(B12,Master!$E$5:$E$200,0)),"",INDEX(Master!$F$5:$F$200,MATCH(B12,Master!$E$5:$E$200,0)))) | D12: =IF(B12="","",IF(ISNA(MATCH(B12,Master!$E$5:$E$200,0)),"",INDEX(Master!$G$5:$G$200,MATCH(B12,Master!$E$5:$E$200,0)))) | F12: KOBICH | J12: CRATE
A13: 9 | C13: =IF(B13="","",IF(ISNA(MATCH(B13,Master!$E$5:$E$200,0)),"",INDEX(Master!$F$5:$F$200,MATCH(B13,Master!$E$5:$E$200,0)))) | D13: =IF(B13="","",IF(ISNA(MATCH(B13,Master!$E$5:$E$200,0)),"",INDEX(Master!$G$5:$G$200,MATCH(B13,Master!$E$5:$E$200,0)))) | F13: GAULI FLOWER | J13: LITRE
A14: 10 | C14: =IF(B14="","",IF(ISNA(MATCH(B14,Master!$E$5:$E$200,0)),"",INDEX(Master!$F$5:$F$200,MATCH(B14,Master!$E$5:$E$200,0)))) | D14: =IF(B14="","",IF(ISNA(MATCH(B14,Master!$E$5:$E$200,0)),"",INDEX(Master!$G$5:$G$200,MATCH(B14,Master!$E$5:$E$200,0)))) | F14: BINAPATTE KA FLOWER | J14: GUNI
A15: 11 | C15: =IF(B15="","",IF(ISNA(MATCH(B15,Master!$E$5:$E$200,0)),"",INDEX(Master!$F$5:$F$200,MATCH(B15,Master!$E$5:$E$200,0)))) | D15: =IF(B15="","",IF(ISNA(MATCH(B15,Master!$E$5:$E$200,0)),"",INDEX(Master!$G$5:$G$200,MATCH(B15,Master!$E$5:$E$200,0)))) | F15: LAUKI
A16: 12 | C16: =IF(B16="","",IF(ISNA(MATCH(B16,Master!$E$5:$E$200,0)),"",INDEX(Master!$F$5:$F$200,MATCH(B16,Master!$E$5:$E$200,0)))) | D16: =IF(B16="","",IF(ISNA(MATCH(B16,Master!$E$5:$E$200,0)),"",INDEX(Master!$G$5:$G$200,MATCH(B16,Master!$E$5:$E$200,0)))) | F16: BHINDI
A17: 13 | C17: =IF(B17="","",IF(ISNA(MATCH(B17,Master!$E$5:$E$200,0)),"",INDEX(Master!$F$5:$F$200,MATCH(B17,Master!$E$5:$E$200,0)))) | D17: =IF(B17="","",IF(ISNA(MATCH(B17,Master!$E$5:$E$200,0)),"",INDEX(Master!$G$5:$G$200,MATCH(B17,Master!$E$5:$E$200,0)))) | F17: BRINJAL
A18: 14 | C18: =IF(B18="","",IF(ISNA(MATCH(B18,Master!$E$5:$E$200,0)),"",INDEX(Master!$F$5:$F$200,MATCH(B18,Master!$E$5:$E$200,0)))) | D18: =IF(B18="","",IF(ISNA(MATCH(B18,Master!$E$5:$E$200,0)),"",INDEX(Master!$G$5:$G$200,MATCH(B18,Master!$E$5:$E$200,0)))) | F18: TINDORA
A19: 15 | C19: =IF(B19="","",IF(ISNA(MATCH(B19,Master!$E$5:$E$200,0)),"",INDEX(Master!$F$5:$F$200,MATCH(B19,Master!$E$5:$E$200,0)))) | D19: =IF(B19="","",IF(ISNA(MATCH(B19,Master!$E$5:$E$200,0)),"",INDEX(Master!$G$5:$G$200,MATCH(B19,Master!$E$5:$E$200,0)))) | F19: PARVAL
A20: 16 | C20: =IF(B20="","",IF(ISNA(MATCH(B20,Master!$E$5:$E$200,0)),"",INDEX(Master!$F$5:$F$200,MATCH(B20,Master!$E$5:$E$200,0)))) | D20: =IF(B20="","",IF(ISNA(MATCH(B20,Master!$E$5:$E$200,0)),"",INDEX(Master!$G$5:$G$200,MATCH(B20,Master!$E$5:$E$200,0)))) | F20: TURIYA
A21: 17 | C21: =IF(B21="","",IF(ISNA(MATCH(B21,Master!$E$5:$E$200,0)),"",INDEX(Master!$F$5:$F$200,MATCH(B21,Master!$E$5:$E$200,0)))) | D21: =IF(B21="","",IF(ISNA(MATCH(B21,Master!$E$5:$E$200,0)),"",INDEX(Master!$G$5:$G$200,MATCH(B21,Master!$E$5:$E$200,0)))) | F21: SIMLA MIRCH
A22: 18 | C22: =IF(B22="","",IF(ISNA(MATCH(B22,Master!$E$5:$E$200,0)),"",INDEX(Master!$F$5:$F$200,MATCH(B22,Master!$E$5:$E$200,0)))) | D22: =IF(B22="","",IF(ISNA(MATCH(B22,Master!$E$5:$E$200,0)),"",INDEX(Master!$G$5:$G$200,MATCH(B22,Master!$E$5:$E$200,0)))) | F22: FANSI
A23: 19 | C23: =IF(B23="","",IF(ISNA(MATCH(B23,Master!$E$5:$E$200,0)),"",INDEX(Master!$F$5:$F$200,MATCH(B23,Master!$E$5:$E$200,0)))) | D23: =IF(B23="","",IF(ISNA(MATCH(B23,Master!$E$5:$E$200,0)),"",INDEX(Master!$G$5:$G$200,MATCH(B23,Master!$E$5:$E$200,0)))) | F23: GUVAR
A24: 20 | C24: =IF(B24="","",IF(ISNA(MATCH(B24,Master!$E$5:$E$200,0)),"",INDEX(Master!$F$5:$F$200,MATCH(B24,Master!$E$5:$E$200,0)))) | D24: =IF(B24="","",IF(ISNA(MATCH(B24,Master!$E$5:$E$200,0)),"",INDEX(Master!$G$5:$G$200,MATCH(B24,Master!$E$5:$E$200,0)))) | F24: SARAGVA SING
A25: 21 | C25: =IF(B25="","",IF(ISNA(MATCH(B25,Master!$E$5:$E$200,0)),"",INDEX(Master!$F$5:$F$200,MATCH(B25,Master!$E$5:$E$200,0)))) | D25: =IF(B25="","",IF(ISNA(MATCH(B25,Master!$E$5:$E$200,0)),"",INDEX(Master!$G$5:$G$200,MATCH(B25,Master!$E$5:$E$200,0)))) | F25: GREEN PEACE
A26: 22 | C26: =IF(B26="","",IF(ISNA(MATCH(B26,Master!$E$5:$E$200,0)),"",INDEX(Master!$F$5:$F$200,MATCH(B26,Master!$E$5:$E$200,0)))) | D26: =IF(B26="","",IF(ISNA(MATCH(B26,Master!$E$5:$E$200,0)),"",INDEX(Master!$G$5:$G$200,MATCH(B26,Master!$E$5:$E$200,0)))) | F26: KATARGAM PAP
... A34: 30 | C34: =IF(B34="","",IF(ISNA(MATCH(B34,Master!$E$5:$E$200,0)),"",INDEX(Master!$F$5:$F$200,MATCH(B34,Master!$E$5:$E$200,0)))) | D34: =IF(B34="","",IF(ISNA(MATCH(B34,Master!$E$5:$E$200,0)),"",INDEX(Master!$G$5:$G$200,MATCH(B34,Master!$E$5:$E$200,0)))) | F34: CORN (MAKKAI)
F35: METHI
A36: Rate auto-fills from Master. Type over any rate cell to quote a different price for this customer only. | F36: PALAK
F37: PUDINA
F38: KADI PATTA
F39: GREEN ONION
F40: KACCHA BANANA
F41: RED SIMLA
F42: YELLOW SIMLA
F43: BROKALI
F44: GREEN TEA
F45: BABY CORN
F46: LETTUCE
F47: CELERY
...
